<?xml version="1.0"?>
<robot xmlns:xacro="http://www.ros.org/wiki/xacro" name="robot">

  <xacro:include filename="inertial_macros.xacro"/>

  <!-- Materials -->
  <material name="white"><color rgba="1 1 1 1"/></material>
  <material name="orange"><color rgba="1 0.3 0.1 1"/></material>
  <material name="blue"><color rgba="0.2 0.2 1 1"/></material>
  <material name="black"><color rgba="0 0 0 1"/></material>
  <material name="red"><color rgba="1 0 0 1"/></material>

  <!-- Base Link -->
  <link name="base_link"/>

  <!-- Base Footprint -->
  <link name="base_footprint"/>
  <joint name="base_footprint_joint" type="fixed">
    <parent link="base_link"/>
    <child link="base_footprint"/>
    <origin xyz="0 0 0" rpy="0 0 0"/>
  </joint>

  <!-- Chassis -->
  <joint name="chassis_joint" type="fixed">
    <parent link="base_link"/>
    <child link="chassis"/>
    <origin xyz="-0.1 0 0"/>
  </joint>

  <link name="chassis">
    <visual>
      <origin xyz="0.1 0 0.08"/>
      <geometry><cylinder radius="0.1" length="0.08"/></geometry>
      <material name="orange"/>
    </visual>
    <collision>
      <origin xyz="0.1 0 0.08"/>
      <geometry><cylinder radius="0.1" length="0.08"/></geometry>
    </collision>
    <xacro:inertial_cylinder mass="0.5" radius="0.1" length="0.08">
      <origin xyz="0 0 0" rpy="0 0 0"/>
    </xacro:inertial_cylinder>
  </link>

  <!-- Left Wheel -->
  <joint name="left_wheel_joint" type="continuous">
    <parent link="base_link"/>
    <child link="left_wheel"/>
    <origin xyz="0 0.06 0.03" rpy="-${pi/2} 0 0"/>
    <axis xyz="0 0 1"/>
  </joint>

  <link name="left_wheel">
    <visual><geometry><cylinder radius="0.035" length="0.03"/></geometry><material name="blue"/></visual>
    <collision><geometry><cylinder radius="0.035" length="0.03"/></geometry></collision>
    <xacro:inertial_cylinder mass="0.1" length="0.03" radius="0.035">
      <origin xyz="0 0 0" rpy="0 0 0"/>
    </xacro:inertial_cylinder>
  </link>

  <!-- Right Wheel -->
  <joint name="right_wheel_joint" type="continuous">
    <parent link="base_link"/>
    <child link="right_wheel"/>
    <origin xyz="0 -0.06 0.03" rpy="${pi/2} 0 0"/>
    <axis xyz="0 0 -1"/>
  </joint>

  <link name="right_wheel">
    <visual><geometry><cylinder radius="0.035" length="0.03"/></geometry><material name="blue"/></visual>
    <collision><geometry><cylinder radius="0.035" length="0.03"/></geometry></collision>
    <xacro:inertial_cylinder mass="0.1" length="0.03" radius="0.035">
      <origin xyz="0 0 0" rpy="0 0 0"/>
    </xacro:inertial_cylinder>
  </link>

  <!-- Caster Wheel -->
  <joint name="caster_wheel_joint" type="fixed">
    <parent link="chassis"/>
    <child link="caster_wheel"/>
    <origin xyz="0.15 0 0.03"/>
  </joint>

  <link name="caster_wheel">
    <visual><geometry><sphere radius="0.03"/></geometry><material name="black"/></visual>
    <collision><geometry><sphere radius="0.03"/></geometry></collision>
    <xacro:inertial_sphere mass="0.1" radius="0.03">
      <origin xyz="0 0 0" rpy="0 0 0"/>
    </xacro:inertial_sphere>
  </link>

  <!-- LiDAR Base -->
  <joint name="laser_joint" type="fixed">
    <parent link="chassis"/>
    <child link="laser_frame"/>
    <origin xyz="0.05 0 0.03"/>
  </joint>

  <link name="laser_frame">
    <visual><geometry><sphere radius="0.03"/></geometry><material name="red"/></visual>
    <collision><geometry><sphere radius="0.03"/></geometry><material name="red"/></collision>
    <xacro:inertial_sphere mass="0.1" radius="0.03">
      <origin xyz="0 0 0" rpy="0 0 0"/>
    </xacro:inertial_sphere>
  </link>

</robot>